<?xml version="1.0" ?>
<!-- =================================================================================== -->
<!-- |    This document was autogenerated by xacro from my_robot_integration.urdf.xacro | -->
<!-- |    EDITING THIS FILE BY HAND IS NOT RECOMMENDED                                 | -->
<!-- =================================================================================== -->
<!-- Name your robot here -->
<robot name="toy_car2">
  <link name="dummy_link">
    <pose>0 0 0 0 0 0</pose>
  </link>
  <joint name="dummy_joint" type="fixed">
    <parent link="dummy_link"/>
    <child link="base_link"/>
  </joint>
  <link name="base_link">
    <inertial>
      <origin rpy="0 0 0" xyz="0.000221429427403003 -1.24851696461115E-08 0.27917692187955"/>
      <mass value="36.8785516604364"/>
      <inertia ixx="0.79890865637271" ixy="-1.77070587701046E-07" ixz="0.000208674706116099" iyy="2.84391870850074" iyz="-9.4067382562074E-09" izz="3.6072349284976"/>
    </inertial>
    <visual>
      <origin rpy="0 0 0" xyz="0 0 0"/>
      <geometry>
        <mesh filename="package://toy_car2/meshes/base_link.STL"/>
      </geometry>
      <material name="">
        <color rgba="0.792156862745098 0.819607843137255 0.933333333333333 1"/>
      </material>
    </visual>
    <collision>
      <origin rpy="0 0 0" xyz="0 0 0"/>
      <geometry>
        <mesh filename="package://toy_car2/meshes/base_link.STL"/>
      </geometry>
    </collision>
  </link>
  <link name="A_front_right">
    <inertial>
      <origin rpy="0 0 0" xyz="0.0150990697167273 -0.104658870076511 -0.0015787419924212"/>
      <mass value="0.457752348264091"/>
      <inertia ixx="0.00146712127834145" ixy="0.000407296110616886" ixz="2.58653064273643E-05" iyy="0.000397741684591518" iyz="-4.25864298426465E-05" izz="0.00171179231489269"/>
    </inertial>
    <visual>
      <origin rpy="0 0 0" xyz="0 0 0"/>
      <geometry>
        <mesh filename="package://toy_car2/meshes/A_front_right.STL"/>
      </geometry>
      <material name="">
        <color rgba="0.792156862745098 0.819607843137255 0.933333333333333 1"/>
      </material>
    </visual>
    <collision>
      <origin rpy="0 0 0" xyz="0 0 0"/>
      <geometry>
        <mesh filename="package://toy_car2/meshes/A_front_right.STL"/>
      </geometry>
    </collision>
  </link>
  <joint name="AFR" type="revolute">
    <origin rpy="1.5707963267949 0 -1.61192452402842" xyz="0.247423936981343 -0.185921848445938 0.266325256317116"/>
    <parent link="base_link"/>
    <child link="A_front_right"/>
    <axis xyz="0 1 0"/>
    <limit effort="100" lower="-0.5" upper="0.5" velocity="10"/>
  </joint>
  <link name="W_front_right">
    <inertial>
      <origin rpy="0 0 0" xyz="-0.000931356944304906 -0.00789834852749627 -0.0281810506956433"/>
      <mass value="1.17708227302182"/>
      <inertia ixx="0.00328764997156677" ixy="3.77647733281346E-06" ixz="3.6368422779933E-05" iyy="0.00331923097570858" iyz="0.000308421470702055" izz="0.00625738068428431"/>
    </inertial>
    <visual>
      <origin rpy="0 0 0" xyz="0 0 0"/>
      <geometry>
        <mesh filename="package://toy_car2/meshes/W_front_right.STL"/>
      </geometry>
      <material name="">
        <color rgba="0.298039215686275 0.298039215686275 0.298039215686275 1"/>
      </material>
    </visual>
    <collision>
      <origin rpy="0 0 0" xyz="0 0 0"/>
      <geometry>
        <mesh filename="package://toy_car2/meshes/W_front_right.STL"/>
      </geometry>
    </collision>
  </link>
  <joint name="WFR" type="continuous">
    <origin rpy="1.5707963267949 -0.117375913875404 -1.5707963267949" xyz="0.0478820242804267 -0.1651 0"/>
    <parent link="A_front_right"/>
    <child link="W_front_right"/>
    <axis xyz="0 0 1"/>
    <limit effort="10" lower="-10000" upper="10000" velocity="100"/>
  </joint>
  <link name="A_front_left">
    <inertial>
      <origin rpy="0 0 0" xyz="0.0151813811159988 -0.104658870076511 -3.33066907387547E-16"/>
      <mass value="0.457752348264091"/>
      <inertia ixx="0.00146441683057283" ixy="0.000409516453552704" ixz="2.01255028267622E-18" iyy="0.000397741684591517" iyz="-5.0098770517519E-18" izz="0.00171449676266131"/>
    </inertial>
    <visual>
      <origin rpy="0 0 0" xyz="0 0 0"/>
      <geometry>
        <mesh filename="package://toy_car2/meshes/A_front_left.STL"/>
      </geometry>
      <material name="">
        <color rgba="0.792156862745098 0.819607843137255 0.933333333333333 1"/>
      </material>
    </visual>
    <collision>
      <origin rpy="0 0 0" xyz="0 0 0"/>
      <geometry>
        <mesh filename="package://toy_car2/meshes/A_front_left.STL"/>
      </geometry>
    </collision>
  </link>
  <joint name="AFL" type="revolute">
    <origin rpy="1.57079632679489 0 1.62685492208242" xyz="0.247423936981343 0.185921848445937 0.266325256317116"/>
    <parent link="base_link"/>
    <child link="A_front_left"/>
    <axis xyz="0 1 0"/>
    <limit effort="100" lower="-0.5" upper="0.5" velocity="10"/>
  </joint>
  <link name="W_front_left">
    <inertial>
      <origin rpy="0 0 0" xyz="-4.16333634234434E-17 0 -0.0192081204890179"/>
      <mass value="1.17708227302182"/>
      <inertia ixx="0.00328720465716001" ixy="5.42524602716379E-19" ixz="7.04731412115578E-19" iyy="0.00328720465716001" iyz="-2.15485181781494E-18" izz="0.00628985231723965"/>
    </inertial>
    <visual>
      <origin rpy="0 0 0" xyz="0 0 0"/>
      <geometry>
        <mesh filename="package://toy_car2/meshes/W_front_left.STL"/>
      </geometry>
      <material name="">
        <color rgba="0.298039215686275 0.298039215686275 0.298039215686275 1"/>
      </material>
    </visual>
    <collision>
      <origin rpy="0 0 0" xyz="0 0 0"/>
      <geometry>
        <mesh filename="package://toy_car2/meshes/W_front_left.STL"/>
      </geometry>
    </collision>
  </link>
  <joint name="WFL" type="continuous">
    <origin rpy="-1.5707963267949 -0.407910894812903 1.5707963267949" xyz="0.0572696063994989 -0.1651 0"/>
    <parent link="A_front_left"/>
    <child link="W_front_left"/>
    <axis xyz="0 0 1"/>
    <limit effort="10" lower="-10000" upper="10000" velocity="100"/>
  </joint>
  <link name="A_rear_right">
    <inertial>
      <origin rpy="0 0 0" xyz="-0.0673686188840012 0.060441129923489 -1.66533453693773E-16"/>
      <mass value="0.457752348264091"/>
      <inertia ixx="0.00146441683057283" ixy="0.000409516453552704" ixz="-1.04390562281624E-18" iyy="0.000397741684591517" iyz="3.21199462696269E-18" izz="0.00171449676266131"/>
    </inertial>
    <visual>
      <origin rpy="0 0 0" xyz="0 0 0"/>
      <geometry>
        <mesh filename="package://toy_car2/meshes/A_rear_right.STL"/>
      </geometry>
      <material name="">
        <color rgba="0.792156862745098 0.819607843137255 0.933333333333333 1"/>
      </material>
    </visual>
    <collision>
      <origin rpy="0 0 0" xyz="0 0 0"/>
      <geometry>
        <mesh filename="package://toy_car2/meshes/A_rear_right.STL"/>
      </geometry>
    </collision>
  </link>
  <joint name="ARR" type="fixed">
    <origin rpy="1.5707963267949 0 -1.5707963267949" xyz="-0.260576021006123 -0.268678451285877 0.101225256317116"/>
    <parent link="base_link"/>
    <child link="A_rear_right"/>
    <axis xyz="0 0 0"/>
  </joint>
  <link name="W_rear_right">
    <inertial>
      <origin rpy="0 0 0" xyz="4.16333634234434E-17 1.66533453693773E-16 0.00607227311148334"/>
      <mass value="1.17708227302182"/>
      <inertia ixx="0.00328720465716001" ixy="2.16840434497101E-19" ixz="1.45041811313902E-18" iyy="0.00328720465716001" iyz="-3.68084640345278E-19" izz="0.00628985231723964"/>
    </inertial>
    <visual>
      <origin rpy="0 0 0" xyz="0 0 0"/>
      <geometry>
        <mesh filename="package://toy_car2/meshes/W_rear_right.STL"/>
      </geometry>
      <material name="">
        <color rgba="0.298039215686275 0.298039215686275 0.298039215686275 1"/>
      </material>
    </visual>
    <collision>
      <origin rpy="0 0 0" xyz="0 0 0"/>
      <geometry>
        <mesh filename="package://toy_car2/meshes/W_rear_right.STL"/>
      </geometry>
    </collision>
  </link>
  <joint name="WRR" type="continuous">
    <origin rpy="1.5707963267949 1.00990623756839 -1.5707963267949" xyz="0 0 0"/>
    <parent link="A_rear_right"/>
    <child link="W_rear_right"/>
    <axis xyz="0 0 1"/>
    <limit effort="10" lower="-10000" upper="10000" velocity="100"/>
  </joint>
  <link name="A_rear_left">
    <inertial>
      <origin rpy="0 0 0" xyz="-0.0673686188840013 -0.060441129923489 0"/>
      <mass value="0.457752348264091"/>
      <inertia ixx="0.00146441683057283" ixy="-0.000409516453552704" ixz="-1.55596748238349E-20" iyy="0.000397741684591517" iyz="3.00616238871955E-20" izz="0.00171449676266131"/>
    </inertial>
    <visual>
      <origin rpy="0 0 0" xyz="0 0 0"/>
      <geometry>
        <mesh filename="package://toy_car2/meshes/A_rear_left.STL"/>
      </geometry>
      <material name="">
        <color rgba="0.792156862745098 0.819607843137255 0.933333333333333 1"/>
      </material>
    </visual>
    <collision>
      <origin rpy="0 0 0" xyz="0 0 0"/>
      <geometry>
        <mesh filename="package://toy_car2/meshes/A_rear_left.STL"/>
      </geometry>
    </collision>
  </link>
  <joint name="ARL" type="fixed">
    <origin rpy="-1.5707963267949 0 1.5707963267949" xyz="-0.260576021006123 0.268678451285877 0.101225256317116"/>
    <parent link="base_link"/>
    <child link="A_rear_left"/>
    <axis xyz="0 0 0"/>
  </joint>
  <link name="W_rear_left">
    <inertial>
      <origin rpy="0 0 0" xyz="0 0 0.00607227311148328"/>
      <mass value="1.17708227302182"/>
      <inertia ixx="0.00328720465716001" ixy="2.16840434497101E-19" ixz="1.43780779146268E-19" iyy="0.00328720465716001" iyz="4.19091085393059E-19" izz="0.00628985231723964"/>
    </inertial>
    <visual>
      <origin rpy="0 0 0" xyz="0 0 0"/>
      <geometry>
        <mesh filename="package://toy_car2/meshes/W_rear_left.STL"/>
      </geometry>
      <material name="">
        <color rgba="0.298039215686275 0.298039215686275 0.298039215686275 1"/>
      </material>
    </visual>
    <collision>
      <origin rpy="0 0 0" xyz="0 0 0"/>
      <geometry>
        <mesh filename="package://toy_car2/meshes/W_rear_left.STL"/>
      </geometry>
    </collision>
  </link>
  <joint name="WRL" type="continuous">
    <origin rpy="1.5707963267949 0.407910894812901 -1.5707963267949" xyz="0 0 0"/>
    <parent link="A_rear_left"/>
    <child link="W_rear_left"/>
    <axis xyz="0 0 -1"/>
    <limit effort="10" lower="-10000" upper="10000" velocity="100"/>
  </joint>
  <!-- Transmission -->
  <transmission name="trans_AFR">
    <type>transmission_interface/SimpleTransmission</type>
    <joint name="AFR">
      <hardwareInterface>hardware_interface/EffortJointInterface</hardwareInterface>
    </joint>
    <actuator name="motor_afr">
      <hardwareInterface>hardware_interface/EffortJointInterface</hardwareInterface>
      <mechanicalReduction>1</mechanicalReduction>
    </actuator>
  </transmission>
  <transmission name="trans_AFL">
    <type>transmission_interface/SimpleTransmission</type>
    <joint name="AFL">
      <hardwareInterface>hardware_interface/EffortJointInterface</hardwareInterface>
    </joint>
    <actuator name="motor_afl">
      <hardwareInterface>hardware_interface/EffortJointInterface</hardwareInterface>
      <mechanicalReduction>1</mechanicalReduction>
    </actuator>
  </transmission>
  <transmission name="trans_WRR">
    <type>transmission_interface/SimpleTransmission</type>
    <joint name="WRR">
      <hardwareInterface>hardware_interface/VelocityointInterface</hardwareInterface>
    </joint>
    <actuator name="motor_wrr">
      <hardwareInterface>hardware_interface/VelocityJointInterface</hardwareInterface>
      <mechanicalReduction>1</mechanicalReduction>
    </actuator>
  </transmission>
  <transmission name="trans_WRL">
    <type>transmission_interface/SimpleTransmission</type>
    <joint name="WRL">
      <hardwareInterface>hardware_interface/VelocityJointInterface</hardwareInterface>
    </joint>
    <actuator name="motor_wrl">
      <hardwareInterface>hardware_interface/VelocityJointInterface</hardwareInterface>
      <mechanicalReduction>1</mechanicalReduction>
    </actuator>
  </transmission>
  <link name="base_laser">
    <inertial>
      <origin rpy="0 0 0" xyz="-0.00029774 0.0066667 0.00013047"/>
      <mass value="0.15717"/>
      <inertia ixx="6.7885E-05" ixy="-1.3987E-07" ixz="-8.1554E-07" iyy="0.00013173" iyz="-9.0932E-08" izz="7.1972E-05"/>
    </inertial>
    <visual>
      <origin rpy="0 0 0" xyz="0 0 0"/>
      <geometry>
        <mesh filename="package://toy_car2/meshes/ydlidar.dae"/>
      </geometry>
      <material name="">
        <color rgba="0.64706 0.61961 0.58824 1"/>
      </material>
    </visual>
    <collision>
      <origin rpy="0 0 0" xyz="0 0 0"/>
      <geometry>
        <mesh filename="package://toy_car2/meshes/ydlidar.dae"/>
      </geometry>
    </collision>
  </link>
  <link name="laser_frame">
    <inertial>
      <origin rpy="0 0 0" xyz="-0.00036659 0.00064155 -0.00027052"/>
      <mass value="0.25482"/>
      <inertia ixx="8.9194E-05" ixy="1.8116E-07" ixz="3.6435E-08" iyy="0.00018279" iyz="2.423E-07" izz="0.00011103"/>
    </inertial>
    <!--visual>
      <origin
        xyz="0 0 0"
        rpy="0 0 0" />
      <geometry>
        <mesh
          filename="package://toy_car2/meshes/ydlidar.dae" />
      </geometry>
      <material
        name="">
        <color
          rgba="0.64706 0.61961 0.58824 1" />
      </material>
    </visual-->
    <!--collision>
      <origin
        xyz="0 0 0"
        rpy="0 0 0" />
      <geometry>
        <mesh
          filename="package://toy_car2/meshes/ydlidar.dae" />
      </geometry>
    </collision-->
  </link>
  <joint name="laser_joint" type="fixed">
    <origin rpy="0 0 0" xyz="0 0 0.03172"/>
    <parent link="base_laser"/>
    <child link="laser_frame"/>
    <axis xyz="0 0 0"/>
  </joint>
  <!-- Add your gazebo sensors here -->
  <gazebo reference="base_laser">
    <!-- <gravity>true</gravity> -->
    <!-- Gazebo has fixed set of Sensors types. Check them out here <> -->
    <sensor name="laser" type="ray">
      <!-- Add in your sensor characteristics -->
      <pose> 0 0 0 0 0 0 </pose>
      <visualise>true</visualise>
      <update_rate>40</update_rate>
      <!-- <always_on>true</always_on> -->
      <ray>
        <scan>
          <horizontal>
            <samples>720</samples>
            <resolution>1</resolution>
            <min_angle>-1.570796</min_angle>
            <max_angle>1.570796</max_angle>
          </horizontal>
        </scan>
        <range>
          <min>0.10</min>
          <max>30.0</max>
          <resolution>0.01</resolution>
        </range>
        <noise>
          <type>gaussian</type>
          <mean>0.0</mean>
          <stddev>0.01</stddev>
        </noise>
      </ray>
      <plugin filename="libgazebo_ros_laser.so" name="gazebo_ros_head_hokuyo_controller">
        <!-- Use topic name as /my_robot/scan -->
        <topicName>/toy_car2/scan</topicName>
        <frameName>laser_frame</frameName>
      </plugin>
    </sensor>
  </gazebo>
  <!--  Gazebo plugin for control here is already added for you -->
  <gazebo>
    <plugin filename="libgazebo_ros_control.so" name="gazebo_ros_control">
      <robotNamespace>/toy_car2</robotNamespace>
      <robotSimType>gazebo_ros_control/DefaultRobotHWSim</robotSimType>
      <legacyModeNS>true</legacyModeNS>
    </plugin>
  </gazebo>
  <!-- Create a joint between your robot and sensor -->
  <joint name="lidar" type="fixed">
    <origin rpy="0 0 0" xyz="0 0 0.325"/>
    <parent link="base_link"/>
    <child link="base_laser"/>
    <axis xyz="0 0 0"/>
  </joint>
</robot>
